Workbook
Name SRC_VANZARI: Vanzari!$A$2:$O$2001
Name PARAM_SURSA_CANONICA: _SISTEM!$B$43
Name PARAM_CATEGORIE_FOCUS: _SISTEM!$B$44
Name PARAM_FOAIE_FINALA: _SISTEM!$B$45

Sheet START
A1: C17 · SISTEMATIZARE · munca devine un sistem pe care altcineva il porneste
A3: Ideea mare:
A4: Raportul e gata (T4). Dar l-ai facut tu, o data. In concediu, munca se opreste:
A5: tu esti ocazia. C17 nu mai face raportul - face MUNCA reluabila de altcineva.
A6: O munca facuta de doua ori nu mai e o livrare. E un sistem ascuns in workbook.
A7: Raport gata (C16) -> harta reluabila (_SISTEM) -> altcineva porneste, fara mine.
A9: AHA: O munca facuta de doua ori nu mai e o livrare. E un sistem ascuns in workbook.
A10: MANTRA: Nu o fac din nou. O fac sistem.
A11: MOTTO: Pleci, si munca o reia altcineva.
A13: Ce ai in acest fisier:
A14: Vanzari tabelul fact (neatins, suma conservata cap-coada)
A15: ... (foile C09-C16) procesul care a produs raportul de decizie
... A29: din workbook, fiindca e legata de componentele reale. Nu e o procedura de citit.

Sheet _SISTEM
A1: _SISTEM C17 · harta functionala reluabila a muncii (nativ-Excel, se rupe scoasa din workbook)
A3: START AICI: | B3: =HYPERLINK("#_SISTEM!A1","mergi la inceputul hartii") | C3: (intri de aici la fiecare reluare)
A5: A) COMPONENTE · foile reale ale workbook-ului (navigabile, vii)
A6: componenta (deschide) | B6: rol in proces | C6: randuri completate (oglinda live)
A7: =HYPERLINK("#'Vanzari'!A1","Vanzari") | B7: sursa (fact) | C7: =COUNTA('Vanzari'!A:A)
A8: =HYPERLINK("#'PRODUSE'!A1","PRODUSE") | B8: sursa (dimensiune) | C8: =COUNTA('PRODUSE'!A:A)
A9: =HYPERLINK("#'CLIENTI'!A1","CLIENTI") | B9: sursa (dimensiune) | C9: =COUNTA('CLIENTI'!A:A)
A10: =HYPERLINK("#'Calendar'!A1","Calendar") | B10: sursa (dimensiune) | C10: =COUNTA('Calendar'!A:A)
A11: =HYPERLINK("#'AGENTI'!A1","AGENTI") | B11: sursa (dimensiune) | C11: =COUNTA('AGENTI'!A:A)
A12: =HYPERLINK("#'DEPOZITE'!A1","DEPOZITE") | B12: sursa (dimensiune) | C12: =COUNTA('DEPOZITE'!A:A)
A13: =HYPERLINK("#'Regiuni'!A1","Regiuni") | B13: sursa (dimensiune) | C13: =COUNTA('Regiuni'!A:A)
A14: =HYPERLINK("#'Masuri'!A1","Masuri") | B14: lucru (masuri) | C14: =COUNTA('Masuri'!A:A)
A15: =HYPERLINK("#'Masuri_Context'!A1","Masuri_Context") | B15: lucru (masuri) | C15: =COUNTA('Masuri_Context'!A:A)
A16: =HYPERLINK("#'Comparatii'!A1","Comparatii") | B16: lucru (comparatie) | C16: =COUNTA('Comparatii'!A:A)
A17: =HYPERLINK("#'Interpretare'!A1","Interpretare") | B17: lucru (interpretare) | C17: =COUNTA('Interpretare'!A:A)
A18: =HYPERLINK("#'Vizualizare'!A1","Vizualizare") | B18: iesire (forma) | C18: =COUNTA('Vizualizare'!A:A)
A19: =HYPERLINK("#'Compunere'!A1","Compunere") | B19: iesire (pagina) | C19: =COUNTA('Compunere'!A:A)
A20: =HYPERLINK("#'Sinteza'!A1","Sinteza") | B20: iesire (mesaj) | C20: =COUNTA('Sinteza'!A:A)
A21: =HYPERLINK("#'Livrare'!A1","Livrare") | B21: iesire (raport de decizie) | C21: =COUNTA('Livrare'!A:A)
A23: B) SURSE · o singura sursa de adevar per intrare (named range SRC_)
A24: intrare | B24: sursa unica (SRC_) | C24: randuri (oglinda =ROWS(SRC_))
A25: tabelul fact | B25: SRC_VANZARI -> Vanzari!A2:O2001 | C25: =ROWS(SRC_VANZARI)
A27: C) PASI · ordinea de reluare a muncii, fiecare pas legat de obiectul real
A28: # pas | B28: actiune (deschide obiectul) | C28: obiect atins | D28: rezultat vizibil (oglinda) | E28: candidat C18?
A29: 1 | B29: =HYPERLINK("#'Vanzari'!A1","deschizi tabelul fact (sursa)") | C29: Vanzari | D29: =COUNTA('Vanzari'!A:A)-1 & " randuri" | E29: nu
A30: 2 | B30: =HYPERLINK("#'Masuri'!A1","recalculezi masurile peste fact") | C30: Masuri | D30: =COUNTA('Masuri'!A:A) & " linii masuri" | E30: da (recalcul recurent)
A31: 3 | B31: =HYPERLINK("#'Comparatii'!A1","citesti clasamentul") | C31: Comparatii | D31: =COUNTA('Comparatii'!A:A) & " linii" | E31: da
A32: 4 | B32: =HYPERLINK("#'Interpretare'!A1","iei explicatia (de ce)") | C32: Interpretare | D32: =COUNTA('Interpretare'!A:A) & " linii" | E32: nu
A33: 5 | B33: =HYPERLINK("#'Compunere'!A1","organizezi pagina raportului") | C33: Compunere | D33: =COUNTA('Compunere'!A:A) & " linii" | E33: nu
A34: 6 | B34: =HYPERLINK("#'Sinteza'!A1","iei mesajul esential") | C34: Sinteza | D34: =COUNTA('Sinteza'!A:A) & " linii" | E34: nu
A35: 7 | B35: =HYPERLINK("#'Livrare'!A1","predai raportul de decizie") | C35: Livrare | D35: =COUNTA('Livrare'!A:A) & " linii" | E35: da (predare recurenta)
A37: D) CINE POATE RELUA · profil de competenta (NU ownership, NU nume)
A38: profil de competenta | B38: competenta minima
A39: analist de date instruit | B39: stie tabele structurate, SUMIFS/agregari, navigare intre foi
A41: E) PARAMETRI · convenstiile scoase din cap, ca valori vii (named range PARAM_)
A42: parametru | B42: valoare | C42: folosit la
A43: PARAM_SURSA_CANONICA | B43: Vanzari | C43: pasul 1 (sursa unica a faptelor)
A44: PARAM_CATEGORIE_FOCUS | B44: Hardware | C44: pasii de raport (categoria pe care se concentreaza decizia)
A45: PARAM_FOAIE_FINALA | B45: Livrare | C45: pasul final (unde sta raportul de decizie)
A47: F) PORNIRE / RELUARE + GRANITA C17->C18 + TEST ANTI-SOP
...

Sheet Vanzari
A1: nr_factura | B1: data_factura | C1: client_nume | D1: judet | E1: cod_produs | F1: produs_nume | G1: categorie | H1: cantitate | I1: pret_unitar | J1: valoare_neta | K1: cota_tva | L1: valoare_tva | M1: valoare_totala | N1: moneda | O1: marja_estimata
A2: F-2025-00001 | B2: 45809 | C2: SC PROVITA MEDICAL SRL | D2: Brașov | E2: PRD-001 | F2: Laptop business 15" | G2: Hardware | H2: 5 | I2: 2460.21 | J2: 12301.05 | K2: 0.19 | L2: 2337.2 | M2: 14638.25 | N2: RON | O2: 1476.13
A3: F-2025-00002 | B3: 45809 | C3: SC AROMET TRADING SRL | D3: București | E3: PRD-005 | F3: Tastatura+mouse wireless | G3: Hardware | H3: 10 | I3: 257.67 | J3: 2576.7 | K3: 0.19 | L3: 489.57 | M3: 3066.27 | N3: RON | O3: 309.2
A4: F-2025-00003 | B4: 45809 | C4: SC PROVITA MEDICAL SRL | D4: Brașov | E4: PRD-006 | F4: Licenta Office 365 anuala | G4: Software | H4: 25 | I4: 720.27 | J4: 18006.75 | K4: 0.19 | L4: 3421.28 | M4: 21428.03 | N4: RON | O4: 8103.04
A5: F-2025-00004 | B5: 45809 | C5: SC ELECTROBUILD SRL | D5: București | E5: PRD-008 | F5: Backup cloud 1TB anual | G5: Software | H5: 1 | I5: 452.97 | J5: 452.97 | K5: 0.19 | L5: 86.06 | M5: 539.03 | N5: RON | O5: 203.84
A6: F-2025-00005 | B6: 45810 | C6: SC TEHNOPLUS SERVICE SRL | D6: Sibiu | E6: PRD-007 | F6: Antivirus enterprise 1an | G6: Software | H6: 1 | I6: 173.29 | J6: 173.29 | K6: 0.19 | L6: 32.93 | M6: 206.22 | N6: RON | O6: 77.98
A7: F-2025-00006 | B7: 45810 | C7: SC TEHNOPLUS SERVICE SRL | D7: Sibiu | E7: PRD-003 | F7: Server tower 16GB | G7: Hardware | H7: 5 | I7: 4183.33 | J7: 20916.65 | K7: 0.19 | L7: 3974.16 | M7: 24890.81 | N7: RON | O7: 2510
A8: F-2025-00007 | B8: 45810 | C8: SC DACTECH SOLUTIONS SRL | D8: Cluj | E8: PRD-010 | F8: Toner laser negru | G8: Consumabile | H8: 5 | I8: 334.79 | J8: 1673.95 | K8: 0.19 | L8: 318.05 | M8: 1992 | N8: RON | O8: 368.27
A9: F-2025-00008 | B9: 45810 | C9: SC VECTOR CONSULT SRL | D9: Mureș | E9: PRD-009 | F9: Hartie A4 500coli (pachet) | G9: Consumabile | H9: 50 | I9: 29.13 | J9: 1456.5 | K9: 0.19 | L9: 276.74 | M9: 1733.24 | N9: RON | O9: 320.43
A10: F-2025-00009 | B10: 45811 | C10: SC INTEGROMED SA | D10: Timiș | E10: PRD-005 | F10: Tastatura+mouse wireless | G10: Hardware | H10: 1 | I10: 244.11 | J10: 244.11 | K10: 0.05 | L10: 12.21 | M10: 256.32 | N10: RON | O10: 29.29
A11: F-2025-00010 | B11: 45811 | C11: SC METALPLAST INVEST SA | D11: București | E11: PRD-004 | F11: Imprimanta multifunctionala | G11: Hardware | H11: 2 | I11: 903.53 | J11: 1807.06 | K11: 0.19 | L11: 343.34 | M11: 2150.4 | N11: RON | O11: 216.85
A12: F-2025-00011 | B12: 45811 | C12: SC TEHNOPLUS SERVICE SRL | D12: Sibiu | E12: PRD-001 | F12: Laptop business 15" | G12: Hardware | H12: 1 | I12: 2486.84 | J12: 2486.84 | K12: 0.19 | L12: 472.5 | M12: 2959.34 | N12: RON | O12: 298.42
A13: F-2025-00012 | B13: 45811 | C13: SC METALPLAST INVEST SA | D13: București | E13: PRD-006 | F13: Licenta Office 365 anuala | G13: Software | H13: 1 | I13: 738.68 | J13: 738.68 | K13: 0.19 | L13: 140.35 | M13: 879.03 | N13: RON | O13: 332.41
... A2001: F-2025-02000 | B2001: 46173 | C2001: SC AROMET TRADING SRL | D2001: București | E2001: PRD-001 | F2001: Laptop business 15" | G2001: Hardware | H2001: 1 | I2001: 2325.79 | J2001: 2325.79 | K2001: 0.19 | L2001: 441.9 | M2001: 2767.69 | N2001: RON | O2001: 279.09

Sheet PRODUSE
A1: cod_produs | B1: nume_produs | C1: categorie | D1: pret_baza
A2: PRD-001 | B2: Laptop business 15" | C2: Hardware | D2: 2400
A3: PRD-002 | B3: Monitor 27" 4K | C3: Hardware | D3: 1100
A4: PRD-003 | B4: Server tower 16GB | C4: Hardware | D4: 4200
A5: PRD-004 | B5: Imprimanta multifunctionala | C5: Hardware | D5: 900
A6: PRD-005 | B6: Tastatura+mouse wireless | C6: Hardware | D6: 250
A7: PRD-006 | B7: Licenta Office 365 anuala | C7: Software | D7: 750
A8: PRD-007 | B8: Antivirus enterprise 1an | C8: Software | D8: 180
A9: PRD-008 | B9: Backup cloud 1TB anual | C9: Software | D9: 450
A10: PRD-009 | B10: Hartie A4 500coli (pachet) | C10: Consumabile | D10: 28
A11: PRD-010 | B11: Toner laser negru | C11: Consumabile | D11: 350
A12: PRD-011 | B12: Cablu HDMI 2m | C12: Consumabile | D12: 45
A13: PRD-012 | B13: Instalare retea LAN (ora) | C13: Servicii | D13: 180
A14: PRD-013 | B14: Mentenanta IT lunara | C14: Servicii | D14: 1200

Sheet CLIENTI
A1: cod_client | B1: nume_client | C1: judet
A2: CL-001 | B2: SC AROMET TRADING SRL | C2: București
A3: CL-002 | B3: SC DACTECH SOLUTIONS SRL | C3: Cluj
A4: CL-003 | B4: SC INTEGROMED SA | C4: Timiș
A5: CL-004 | B5: SC NORDIS DISTRIBUTIE SRL | C5: Iași
A6: CL-005 | B6: SC METALPLAST INVEST SA | C6: București
A7: CL-006 | B7: SC OMEGA SOFT SRL | C7: Cluj
A8: CL-007 | B8: SC PROVITA MEDICAL SRL | C8: Brașov
A9: CL-008 | B9: SC RAPID LOGISTIC SA | C9: Constanța
A10: CL-009 | B10: SC SOLARIS ENERGY SRL | C10: Timiș
A11: CL-010 | B11: SC TEHNOPLUS SERVICE SRL | C11: Sibiu
A12: CL-011 | B12: SC UNIFOOD DISTRIBUTION SA | C12: București
... A16: CL-015 | B16: SC FARMAVITAL DISTRIBUTIE SA | C16: Iași

Sheet Calendar
A1: data | B1: an | C1: luna_nr | D1: luna_nume | E1: trimestru | F1: zi_saptamana
A2: 45809 | B2: 2025 | C2: 6 | D2: iunie | E2: T2 | F2: duminica
A3: 45810 | B3: 2025 | C3: 6 | D3: iunie | E3: T2 | F3: luni
A4: 45811 | B4: 2025 | C4: 6 | D4: iunie | E4: T2 | F4: marti
A5: 45812 | B5: 2025 | C5: 6 | D5: iunie | E5: T2 | F5: miercuri
A6: 45813 | B6: 2025 | C6: 6 | D6: iunie | E6: T2 | F6: joi
A7: 45814 | B7: 2025 | C7: 6 | D7: iunie | E7: T2 | F7: vineri
A8: 45815 | B8: 2025 | C8: 6 | D8: iunie | E8: T2 | F8: sambata
A9: 45816 | B9: 2025 | C9: 6 | D9: iunie | E9: T2 | F9: duminica
A10: 45817 | B10: 2025 | C10: 6 | D10: iunie | E10: T2 | F10: luni
A11: 45818 | B11: 2025 | C11: 6 | D11: iunie | E11: T2 | F11: marti
A12: 45819 | B12: 2025 | C12: 6 | D12: iunie | E12: T2 | F12: miercuri
A13: 45820 | B13: 2025 | C13: 6 | D13: iunie | E13: T2 | F13: joi
... A365: 46173 | B365: 2026 | C365: 5 | D365: mai | E365: T2 | F365: duminica

Sheet AGENTI
A1: cod_agent | B1: nume_agent
A2: AG-001 | B2: Vasile Popescu
A3: AG-002 | B3: Maria Ionescu
A4: AG-003 | B4: Andrei Marin
A5: AG-004 | B5: Cristina Dumitrescu
A6: AG-005 | B6: Bogdan Stanescu
A7: AG-006 | B7: Elena Radu

Sheet DEPOZITE
A1: cod_depozit | B1: nume_depozit
A2: DEP-BUC | B2: Depozit Bucuresti Central
A3: DEP-CLJ | B3: Depozit Cluj-Napoca
A4: DEP-TM | B4: Depozit Timisoara
A5: DEP-IS | B5: Depozit Iasi
A6: DEP-CTA | B6: Depozit Constanta

Sheet Regiuni
A1: judet | B1: regiune
A2: Brașov | B2: Transilvania
A3: București | B3: Muntenia
A4: Cluj | B4: Transilvania
A5: Constanța | B5: Dobrogea
A6: Iași | B6: Moldova
A7: Mureș | B7: Transilvania
A8: Sibiu | B8: Transilvania
A9: Timiș | B9: Banat

Sheet Masuri
A1: MASURI C10 · definitiile: o singura sursa de adevar, baza, reper, semnal
A3: 1) MASURILE · single source of truth (definite o singura data, reutilizabile)
A4: cod | B4: masura | C4: definitie | D4: formula (live) | E4: rezultat | F4: baza de raportare
A5: M1 | B5: Total valoare | C5: suma valorii nete pe tot setul | D5: =ROUND(SUM(Vanzari!J2:J2001),2) | E5: 7986019.4 | F5: tot setul (toate tranzactiile)
A6: M2 | B6: Numar tranzactii | C6: cate tranzactii are setul | D6: =COUNTA(Vanzari!A2:A2001) | E6: 2000 | F6: tot setul
A7: M3 | B7: Valoare medie per tranzactie | C7: M1 impartit la M2 | D7: =ROUND(E5/E6,2) | E7: 3993.01 | F7: numar tranzactii (declarat)
A8: M4 | B8: Valoare medie per client | C8: M1 impartit la numarul de clienti distincti | D8: =ROUND(E5/SUMPRODUCT(1/COUNTIF(Vanzari!C2:C2001,Vanzari!C2:C2001)),2) | E8: 532401.29 | F8: clienti distincti (declarat)
A9: M5 | B9: Valoare medie pe zi activa | C9: M1 impartit la numarul de zile cu vanzari | D9: =ROUND(E5/SUMPRODUCT(1/COUNTIF(Vanzari!B2:B2001,Vanzari!B2:B2001)),2) | E9: 21939.61 | F9: zile active (cu cel putin o vanzare)
A11: 2) REPER / PRAG · masura capata sens raportata la o tinta definita
A12: masura | B12: reper (tinta interna) | C12: formula semnal (live) | D12: semnal
A13: M3 Valoare medie per tranzactie | B13: 3500 | C13: =IF(E7>=B13,"peste reper","sub reper") | D13: peste reper
A15: 3) CIFRA UTILA vs CIFRA DECORATIVA · criteriul de selectie
A16: cifra | B16: statut | C16: de ce
A17: suma valoare_neta | B17: UTILA -> masura M1 | C17: raspunde la o intrebare de business
A18: media valorii per tranzactie | B18: UTILA -> masura M3 | C18: controlabila, are baza si reper
A19: suma numerelor de factura | B19: DECORATIVA | C19: nu raspunde la nicio intrebare reala
A20: media cotei TVA | B20: DECORATIVA | C20: constanta fiscala, nu indicator de decizie
A22: 4) HANDOFF
A23: input de la C09 | B23: model relational interogabil (relatii activate)
A24: output C10 | B24: masuri definite (single source of truth, baza, reper, semnal)
A25: predat catre C11 | B25: compara masurile (clasament/diferenta); C10 nu compara
A26: suma conservata cap-coada | B26: 7986019.4

Sheet Masuri_Context
A1: MASURI_CONTEXT C10 · aceeasi masura, taieturi diferite
A3: Masura demonstrata: Valoare medie per tranzactie (definitia din Masuri!M3).
A4: Scop: dovada ca ACEEASI definitie da rezultat corect pe orice taietura.
A5: NU este clasament. CARE taietura e mai mare se decide la C11, nu aici.
A7: taietura | B7: formula (live) | C7: rezultat
A8: tot setul (overall) | B8: =ROUND(AVERAGE(Vanzari!J2:J2001),2) | C8: 3993.01
A9: categorie = "Hardware" | B9: =ROUND(AVERAGEIF(Vanzari!G2:G2001,"Hardware",Vanzari!J2:J2001),2) | C9: 4050.99
A10: client = "SC AROMET TRADING SRL" | B10: =ROUND(AVERAGEIF(Vanzari!C2:C2001,"SC AROMET TRADING SRL",Vanzari!J2:J2001),2) | C10: 3792.95
A11: luna = 2025-06 | B11: =ROUND(AVERAGEIFS(Vanzari!J2:J2001,Vanzari!B2:B2001,">="&DATE(2025,6,1),Vanzari!B2:B2001,"<"&EDATE(DATE(2025,6,1),1)),2) | C11: 3806.92
A13: Citire: valorile difera pentru ca taietura difera, nu pentru ca masura e alta.
A14: Definitia este identica in toate cele patru cazuri. Aceasta e o masura robusta.

Sheet Comparatii
A1: Actor (categorie) | B1: Masura (valoare_neta) | C1: Rang | D1: Contributie_% | E1: Cumulat_% | F1: Clasa_ABC
A2: Hardware | B2: 3876798.9 | C2: 1 | D2: 48.54 | E2: 48.54 | F2: A
A3: Software | B3: 2401725.8 | C3: 2 | D3: 30.07 | E3: 78.62 | F3: A
A4: Consumabile | B4: 1644165.2 | C4: 3 | D4: 20.59 | E4: 99.21 | F4: C
A5: Servicii | B5: 63329.42 | C5: 4 | D5: 0.79 | E5: 100 | F5: C
A7: TOTAL | B7: 7986019.4 | D7: 100

Sheet Interpretare
A1: INTERPRETARE C12 · de ce arata rezultatul asa, citit din model
A3: 1) INTREBAREA · "De ce?"
A4: rezultat de explicat | B4: sursa | C4: intrebarea
A5: "Hardware" conduce clasamentul valorii | B5: Comparatii (C11) | C5: De ce conduce Hardware, si ce anume il duce acolo?
A7: 2) CAUZA CITITA DIN MODEL · drill sub total (nu ghicit)
A8: factor | B8: tip | C8: formula (live) | D8: valoare | E8: pondere in Hardware (%)
A9: produs: Laptop business 15" | B9: factor principal | C9: =ROUND(SUMIFS(Vanzari!J2:J2001,Vanzari!G2:G2001,"Hardware",Vanzari!F2:F2001,"Laptop business 15"""),2) | D9: 1434342.9 | E9: 37
A10: produs: Server tower 16GB | B10: factor principal | C10: =ROUND(SUMIFS(Vanzari!J2:J2001,Vanzari!G2:G2001,"Hardware",Vanzari!F2:F2001,"Server tower 16GB"),2) | D10: 1313763.4 | E10: 33.9
A11: produs: Monitor 27" 4K | B11: factor principal | C11: =ROUND(SUMIFS(Vanzari!J2:J2001,Vanzari!G2:G2001,"Hardware",Vanzari!F2:F2001,"Monitor 27"" 4K"),2) | D11: 643735.35 | E11: 16.6
A12: client: SC AROMET TRADING SRL | B12: factor principal | C12: =ROUND(SUMIFS(Vanzari!J2:J2001,Vanzari!G2:G2001,"Hardware",Vanzari!C2:C2001,"SC AROMET TRADING SRL"),2) | D12: 724988.75 | E12: 18.7
A13: client: SC INTEGROMED SA | B13: factor principal | C13: =ROUND(SUMIFS(Vanzari!J2:J2001,Vanzari!G2:G2001,"Hardware",Vanzari!C2:C2001,"SC INTEGROMED SA"),2) | D13: 473369.36 | E13: 12.2
A15: 3) FACTORI PRINCIPALI · rezultatul rar are o singura cauza
A16: constatare | B16: dovada (citita mai sus)
A17: nu o cauza unica: doua produse trag impreuna cea mai mare parte din Hardware | B17: primele 2 produse = 70.9% din Hardware
A18: si concentrarea pe clienti contribuie | B18: primul client = 18.7% din Hardware
A20: 4) COINCIDENTA vs CAUZA · ce apare impreuna nu explica automat
A21: observatie | B21: verdict | C21: de ce
A22: Hardware are si cele mai multe tranzactii | B22: COINCIDENTA partiala | C22: volumul mare de tranzactii insoteste rezultatul, dar nu e singura cauza
A23: valoarea medie/tranzactie nu e cea mai mare la Hardware | B23: CAUZA reala = mix | C23: Software are media/tranzactie cea mai mare (5099.21), dar nu conduce totalul: Hardware conduce prin produse-cheie + volum, nu prin pret mediu
A25: 5) CAUZA ASCUNSA DE AGREGARE · apare doar sub total
A26: nivel | B26: ce vezi
A27: la nivel de total (clasament C11) | B27: doar ca "Hardware conduce" (CARE)
A28: cobori sub total (aici) | B28: doua produse duc 70.9% din categorie: cauza reala, ascunsa de totalul agregat
A30: 6) EXPLICATIE VERIFICABILA · insight verbal ancorat in model
A31: insight (fraza) | B31: se verifica in
A32: "Hardware conduce nu pentru ca fiecare vanzare e cea mai mare, ci pentru ca doua produse-cheie si cativa clienti concentrati ii duc 70.9% din valoare; pretul mediu mai mare e la alta categorie." | B32: sectiunile 2-5 de mai sus (formule live pe Vanzari)
A34: 7) HANDOFF · inchidere T3
A35: input de la C11 | B35: clasament (CARE conduce, contributie, ABC)
A36: output C12 | B36: explicatie: DE CE conduce, cauza citita din model, verificabila
A37: treapta T3 ANALIZA | B37: FINALIZATA (corect -> inteles -> interpretat)
A38: predat catre T4 (C13) | B38: raportarea face explicatia vizibila; C12 nu vizualizeaza
A39: suma conservata cap-coada | B39: 7986019.4

Sheet Vizualizare
A1: VIZUALIZARE C13 · forma onesta a unui rezultat, verificata contra cifrei brute
A3: 1) REZULTATUL DE VIZUALIZAT · citit din model (nu inventat)
A4: rezultat | B4: sursa | C4: natura
A5: Diferenta valorii intre primele doua categorii | B5: Comparatii (C11/C12) | C5: comparatie -> forma potrivita = bare cu axa de la zero
A7: 2) CIFRA BRUTA · valorile reale (referinta de adevar)
A8: categorie | B8: valoare (live) | C8: pondere din total (%)
A9: Hardware | B9: =ROUND(SUMIFS(Vanzari!J2:J2001,Vanzari!G2:G2001,"Hardware"),2) | C9: =ROUND(100*SUMIFS(Vanzari!J2:J2001,Vanzari!G2:G2001,"Hardware")/SUM(Vanzari!J2:J2001),1)
A10: Software | B10: =ROUND(SUMIFS(Vanzari!J2:J2001,Vanzari!G2:G2001,"Software"),2) | C10: =ROUND(100*SUMIFS(Vanzari!J2:J2001,Vanzari!G2:G2001,"Software")/SUM(Vanzari!J2:J2001),1)
A11: Consumabile | B11: =ROUND(SUMIFS(Vanzari!J2:J2001,Vanzari!G2:G2001,"Consumabile"),2) | C11: =ROUND(100*SUMIFS(Vanzari!J2:J2001,Vanzari!G2:G2001,"Consumabile")/SUM(Vanzari!J2:J2001),1)
A12: Servicii | B12: =ROUND(SUMIFS(Vanzari!J2:J2001,Vanzari!G2:G2001,"Servicii"),2) | C12: =ROUND(100*SUMIFS(Vanzari!J2:J2001,Vanzari!G2:G2001,"Servicii")/SUM(Vanzari!J2:J2001),1)
A14: 3) FORMA ONESTA vs FORMA CARE MINTE · aceeasi cifra, doua concluzii
A15: forma | B15: axa | C15: ce concluzie sugereaza | D15: verdict
A16: bare cu axa de la zero | B16: porneste de la 0 | C16: diferenta reala de 38.0% intre primele doua categorii | D16: ONESTA
A17: bare cu axa trunchiata | B17: porneste de la a doua valoare | C17: diferenta pare uriasa, desi cifra e aceeasi | D17: MINTE
A18: placinta cu prea multe felii | B18: fara axa | C18: ordinea si marimea categoriilor devin greu de citit | D18: MINTE
A20: 4) VERIFICARE · vizualul citit singur = cifra bruta?
A21: proba | B21: rezultat
A22: concluzia din forma onesta | B22: Hardware conduce, cu 38.0% peste Software
A23: concluzia din cifra bruta (sectiunea 2) | B23: identica: Hardware conduce cu aceeasi diferenta
A24: al doilea ochi (doar graficul, fara cifra) | B24: trage aceeasi concluzie -> forma e onesta
A26: 5) CELE 6 REGULI DE ONESTITATE A FORMEI
A27: # | B27: deformare | C27: regula onesta
A28: 1 | B28: Axa care exagereaza | C28: axa pleaca de la zero, sau abaterea e declarata explicit
A29: 2 | B29: Tipul de grafic nepotrivit | C29: tipul urmeaza natura rezultatului
A30: 3 | B30: Scala care inventeaza relatii | C30: o singura scala liniara, declarata
A31: 4 | B31: Codarea care sugereaza fals | C31: o singura dimensiune codata coerent
A32: 5 | B32: Agregarea care ascunde variatia | C32: arati distributia / variatia, nu doar media
A33: 6 | B33: Eticheta / unitatea / contextul lipsa | C33: fiecare vizual poarta unitate, eticheta si context
A35: 6) HANDOFF · C13 face obiectul adevarat, C14 il asaza in pagina
A36: input de la T3 (C12) | B36: rezultat corect, explicat, dar mut in model
A37: output C13 | B37: obiect vizual onest, verificat contra cifrei brute
A38: predat catre C14 | B38: compunerea paginii / dashboard-ului (organizare spatiala)
A39: C13 NU face | B39: dashboard, pagina, layout, mesaj, livrare
A40: suma conservata cap-coada | B40: 7986019.4

Sheet Compunere
A1: COMPUNERE C14 · asezarea spatiala a mai multor obiecte vizuale intr-o pagina de raport
A3: 1) OBIECTELE VIZUALE PRIMITE · de la treapta de vizualizare (nu redesenate, tip neschimbat)
A4: obiect | B4: tip (neschimbat) | C4: ce arata
A5: Clasament categorii | B5: bare cu axa de la zero | C5: comparatia valorii intre categorii
A6: Pondere din total | B6: structura parte-din-tot | C6: cat reprezinta fiecare categorie
A7: Context masura | B7: indicator (numar mare) | C7: o singura cifra de referinta
A9: 2) INTREBAREA C14 · ce vede ochiul intai? · raspunsul guverneaza focarul
A10: element | B10: valoare
A11: raspunsul venit din analiza (ce conteaza) | B11: Hardware conduce, cu 38.0% peste Software
A12: focarul (obiectul atins primul) | B12: clasamentul categoriilor, cu Hardware in frunte
A14: 3) ASEZAREA · pozitie, ordine de citire, grup (acelasi continut, alta dispunere)
A15: obiect | B15: pozitie | C15: ordine de citire | D15: grup
A16: Clasament categorii | B16: sus-stanga (focar) | C16: 1 | D16: rezultatul principal
A17: Pondere din total | B17: langa focar | C17: 2 | D17: rezultatul principal
A18: Context masura | B18: sub focar, mai mic | C18: 3 | D18: suport
A19: Tabel detaliu | B19: jos, retrogradat | C19: 4 | D19: detaliu la cerere
A21: 4) BEFORE / AFTER · aceleasi obiecte, alta asezare, alta decizie
A22: dimensiune | B22: inainte (ordinea productiei) | C22: dupa (compunere guvernata de raspuns)
A23: focar | B23: niciunul, toate egale | C23: unul singur, atins primul
A24: ordine de citire | B24: cronologica, intamplatoare | C24: guvernata de raspuns
A25: greutate vizuala | B25: egala la lucruri inegale | C25: ierarhie pe trei niveluri
A26: spatiu gol | B26: umplut (horror vacui) | C26: deliberat, izoleaza focarul
A27: decizie | B27: intarzie, ochiul rataceste | C27: se prinde in cateva secunde
A29: 5) CELE 6 OPERATII DE COMPUNERE (dezordine -> compozitie pentru decizie)
A30: # | B30: dezordine | C30: operatie de compunere
A31: 1 | B31: Pagina-zid fara focar | C31: stabilesti un singur focar, atins primul
A32: 2 | B32: Esentialul ingropat in colt | C32: esentialul urca in primul punct de contact al ochiului
A33: 3 | B33: Ordinea de productie pe pagina | C33: ordinea de citire guvernata de raspuns
A34: 4 | B34: Greutate egala la lucruri inegale | C34: ierarhie prin marime, pozitie, contrast, spatiu
A35: 5 | B35: Proximitate care minte despre relatii | C35: grupare spatiala a obiectelor legate
A36: 6 | B36: Horror vacui, umpli orice gol | C36: spatiul gol folosit ca instrument de ierarhie
A38: 6) HANDOFF · C14 asaza pagina, C15 ii extrage mesajul
A39: input de la treapta de vizualizare | B39: obiecte vizuale oneste, fiecare adevarat singur
A40: output C14 | B40: pagina de raport coerenta: focar, ierarhie, traseu, grupare, spatiu
A41: predat catre treapta de sintetizare | B41: extragerea si formularea mesajului esential
A42: C14 NU face | B42: obiect nou, mesaj, livrare, re-analiza; nu schimba tipuri de grafice
A43: suma conservata cap-coada | B43: 7986019.4

Sheet Sinteza
A1: SINTEZA C15 · stratul MESAJ · formularea mesajului esential al paginii compuse
A3: 1) PAGINA PRIMITA · de la treapta de compunere (pagina-dovada, nerearanjata)
A4: element | B4: continut
A5: pagina compusa | B5: focar, ierarhie, traseu de citire (mostenite de la C14)
A6: raspunsul venit din analiza (T3), de reformulat ca mesaj | B6: Hardware conduce, cu 38.0% peste Software
A7: stare | B7: pagina ARATA corect; inca nu SPUNE nimic
A9: 2) REZUMAT vs SINTEZA · aceeasi pagina, doua iesiri
A10: tip | B10: ce face | C10: rezultat
A11: rezumat (automat, AI) | B11: scurteaza tot proportional | C11: lista de tot ce e pe pagina, fara ierarhie de sens
A12: sinteza (om) | B12: alege singurul mesaj care conteaza | C12: o singura fraza pe care pagina o dovedeste
A14: 3) MESAJUL ESENTIAL · headline + so-what (text formulat de cursant, nu calculat)
A15: camp | B15: continut (exemplu, fara cifre statice in raportul vizual)
A16: headline (o fraza) | B16: In trimestrul analizat, Hardware duce rezultatul; restul categoriilor raman in urma.
A17: so-what (de ce conteaza) | B17: Daca o singura categorie poarta rezultatul, acolo se uita decidentul intai.
A18: legatura la pagina-dovada | B18: focarul paginii: clasamentul categoriilor, cu Hardware in frunte
A19: NOTA | B19: cifra exacta traieste in pagina/Excel; mesajul o reformuleaza, nu o re-calculeaza
A21: 4) TESTUL "si ce-i cu asta?" · mesaj care muta decizia vs zgomot
A22: fraza candidata | B22: trece testul? | C22: de ce
A23: "Pagina contine 7 categorii si 4 indicatori." | B23: NU | C23: descrie, nu spune ce conteaza (e rezumat)
A24: "O singura categorie duce rezultatul." | B24: DA | C24: fara ea, decidentul s-ar uita altundeva
A25: filtru | B25: fara aceasta fraza, decidentul hotaraste la fel? Daca da, nu e mesajul.
A27: 5) REFORMULARE (E5) · mesajul se adapteaza la schimbare (verbal, NU recalcul)
A28: situatie | B28: ce faci
A29: datele s-au actualizat in amonte (model/T3) | B29: mesajul vechi nu mai e exact
A30: actiunea C15 | B30: reformulezi headline-ul (refaci sinteza); NU recalculezi nimic
A31: cifrele | B31: raman ale modelului; se schimba in amonte, nu in stratul MESAJ
A32: criteriu pastrat | B32: noul mesaj ramane o singura afirmatie sustinuta de pagina: ce conteaza
A34: 6) HANDOFF · C15 formuleaza mesajul, C16 il incadreaza pentru decizie
A35: input de la treapta de compunere | B35: pagina coerenta: focar, ierarhie, traseu
A36: output C15 | B36: mesajul esential (o fraza) + so-what + legatura la pagina-dovada
A37: predat catre treapta de livrare | B37: incadrarea deciziei: ce e de hotarat, pachet pentru decident
A38: C15 NU face | B38: cifra/cauza noua (T3), rearanjare pagina (C14), recomandare/livrare (C16)
A39: regula de aur | B39: mesajul CITESTE din pagina, nu PRODUCE pagina
A40: suma conservata cap-coada | B40: 7986019.4

Sheet Livrare
A1: LIVRARE C16 · foaia-raport de decizie: raportul devine obiect de decizie
A3: 1) DECIZIA CERUTA · ce se hotaraste din raport (citit din rezultat, nu inventat)
A4: decizie ceruta | B4: sursa | C4: tip
A5: Pe ce categorie concentram resursele in ciclul urmator | B5: Comparatii (C11/C12) + agregat pe categorie | C5: decizie de alocare, orientata spre actiune
A7: 2) CADRUL DE DECIZIE · decizie / risc / concluzie / pas urmator (ancorat in agregatul live)
A8: element | B8: continut (ancorat in date)
A9: Concluzie | B9: =CONCATENATE("Categoria ","Hardware"," conduce valoarea neta, cu ",TEXT(ROUND(100*SUMIFS(Vanzari!J2:J2001,Vanzari!G2:G2001,"Hardware")/SUM(Vanzari!J2:J2001),1),"0.0"),"%% din total")
A10: Decizie de luat | B10: =CONCATENATE("Mentinem focusul pe ","Hardware"," sau realocam spre ","Software"," (a doua)?")
A11: Risc | B11: =CONCATENATE("Dependenta de o singura categorie: ","Hardware"," tine ",TEXT(ROUND(100*SUMIFS(Vanzari!J2:J2001,Vanzari!G2:G2001,"Hardware")/SUM(Vanzari!J2:J2001),1),"0.0"),"%% din valoarea neta; prag de alerta de stabilit")
A12: Pas urmator | B12: Actiunea propusa (de scris explicit de decident), ancorata in agregatul de mai jos
A14: 3) CE INTRA IN DECIZIE (cap de foaie) vs CE RAMANE ANEXA
A15: nivel | B15: continut | C15: unde sta
A16: in decizie | B16: agregatul pe categorie (relevant pentru hotarare) | C16: capul foii
A17: anexa | B17: detaliul brut linie cu linie (nr_factura, data_factura, client) | C17: jos / foaie separata
A19: agregat pe categorie (cifra live, referinta de decizie):
A20: categorie | B20: valoare neta (live) | C20: pondere din total (%)
A21: Hardware | B21: =ROUND(SUMIFS(Vanzari!J2:J2001,Vanzari!G2:G2001,"Hardware"),2) | C21: =ROUND(100*SUMIFS(Vanzari!J2:J2001,Vanzari!G2:G2001,"Hardware")/SUM(Vanzari!J2:J2001),1)
A22: Software | B22: =ROUND(SUMIFS(Vanzari!J2:J2001,Vanzari!G2:G2001,"Software"),2) | C22: =ROUND(100*SUMIFS(Vanzari!J2:J2001,Vanzari!G2:G2001,"Software")/SUM(Vanzari!J2:J2001),1)
A23: Consumabile | B23: =ROUND(SUMIFS(Vanzari!J2:J2001,Vanzari!G2:G2001,"Consumabile"),2) | C23: =ROUND(100*SUMIFS(Vanzari!J2:J2001,Vanzari!G2:G2001,"Consumabile")/SUM(Vanzari!J2:J2001),1)
A24: Servicii | B24: =ROUND(SUMIFS(Vanzari!J2:J2001,Vanzari!G2:G2001,"Servicii"),2) | C24: =ROUND(100*SUMIFS(Vanzari!J2:J2001,Vanzari!G2:G2001,"Servicii")/SUM(Vanzari!J2:J2001),1)
A26: 4) VERIFICARE · poate decidentul hotari doar din foaie? (self-standing)
A27: proba | B27: rezultat
A28: decizie + risc + concluzie + pas urmator prezente? | B28: da, in cadrul de decizie (sectiunea 2)
A29: cifra are unitate / perioada / referinta? | B29: da, agregat live + sursa declarata, fara autor langa
A30: se citeste o data si se decide? | B30: da -> raportul e obiect de decizie, nu doar informatie
A32: 5) CELE 6 REGULI ALE FOII-RAPORT DE DECIZIE
A33: # | B33: capcana | C33: regula decision-ready
A34: 1 | B34: Concluzia ingropata | C34: concluzia ceruta sta in prima linie, nu la pagina 14
A35: 2 | B35: Lipsa cadrului de decizie | C35: decizie / risc / concluzie / pas urmator, explicit
A36: 3 | B36: Totul aglomerat in cap | C36: ce nu intra in decizie coboara in anexa, nu dispare
A37: 4 | B37: Risc lasat implicit | C37: riscul se scrie, cu pragul lui
A38: 5 | B38: Raport care se termina in constatare | C38: pasul urmator se scrie, ancorat in date
A39: 6 | B39: Foaie care are nevoie de autor | C39: fiecare cifra poarta unitate, perioada si referinta
A41: 6) HANDOFF · C16 preda decizia gata, C17 o sistematizeaza in T5
A42: input de la C15 | B42: mesajul esential, sintetizat
A43: output C16 | B43: raport decision-ready, predabil ca obiect de decizie
A44: predat catre T5 (C17) | B44: sistematizarea recurenta a raportului (nu e treaba C16)
A45: C16 NU face | B45: sinteza (C15), layout vizual (C14), sistem recurent (C17), logistica
A46: suma conservata cap-coada | B46: 7986019.4
